<?xml version="1.0" encoding="utf-8"?>
<!-- This URDF was automatically created by SolidWorks to URDF Exporter! Originally created by Stephen Brawner (brawner@gmail.com) 
     Commit Version: 1.6.0-4-g7f85cfe  Build Version: 1.6.7995.38578
     For more information, please see http://wiki.ros.org/sw_urdf_exporter -->
<robot name="robot">


  <!-- Thêm base_footprint -->
  <link name="base_footprint">
    <inertial>
      <origin xyz="0 0 0" rpy="0 0 0"/>
      <mass value="0.001"/>
      <inertia ixx="0.0001" ixy="0" ixz="0" iyy="0.0001" iyz="0" izz="0.0001"/>
    </inertial>
  </link>

  <joint name="base_footprint_to_base_link" type="fixed">
    <origin xyz="0 0 0.01" rpy="0 0 0"/>
    <!-- base_footprint thấp hơn base_link 1cm -->
    <parent link="base_footprint"/>
    <child link="base_link"/>

  </joint>

  <link name="base_link">
    <inertial>
      <origin xyz="0.0215695152515472 -0.000328587130316308 0.050565571150473" rpy="0 0 0" />
      <mass value="3.09194293431158" />
      <inertia ixx="0.0231490717238727" ixy="-5.37537219262866E-05" ixz="0.000373686648336405" iyy="0.0130204980494664" iyz="5.42994609787083E-06" izz="0.0352905187406014" />
    </inertial>
    <visual>
      <origin xyz="0 0 0" rpy="0 0 0" />
      <geometry>
        <mesh filename="package://robot/meshes/base_link.STL" />
      </geometry>
      <material name="">
        <color rgba="0.792156862745098 0.819607843137255 0.933333333333333 1" />
      </material>
    </visual>
    <collision>
      <origin xyz="0 0 0" rpy="0 0 0" />
      <geometry>
        <mesh filename="package://robot/meshes/base_link.STL" />
      </geometry>
    </collision>
  </link>

  <!-- BANHDAHUONG_LINK -->
  <link name="Banhdahuong_link">
    <inertial>
      <origin xyz="-5.56455544407641E-05 7.02122885434808E-06 8.53335422783784E-05" rpy="0 0 0" />
      <mass value="0.1" />
      <inertia ixx="9.20819516763883E-07" ixy="3.12073828031739E-09" ixz="-8.67401367828414E-12" iyy="7.17989838752027E-07" iyz="3.45962932407375E-13" izz="9.20875189269629E-07" />
    </inertial>
    <visual>
      <origin xyz="0 0 0" rpy="0 0 0" />
      <geometry>
        <mesh filename="package://robot/meshes/Banhdahuong_link.STL" />
      </geometry>
      <material name="">
        <color rgba="0.792156862745098 0.819607843137255 0.933333333333333 1" />
      </material>
    </visual>
    <collision>
      <origin xyz="0 0 0" rpy="0 0 0" />
      <geometry>
        <mesh filename="package://robot/meshes/Banhdahuong_link.STL" />
      </geometry>
    </collision>
  </link>
  <joint name="Banhdahuong_joint" type="continuous">
    <origin xyz="0.13233 9.9869E-05 0.011166" rpy="0 0 0" />
    <parent link="base_link" />
    <child link="Banhdahuong_link" />
    <axis xyz="-0.015364 0.99988 0" />
  </joint>

  

  <!-- LIDAR_LINK -->
  <link name="Lidar_link">
    <inertial>
      <origin xyz="0.0101056978739759 0.000414595183128693 -0.0355014080835032" rpy="0 0 0" />
      <mass value="0.0941040901843603" />
      <inertia ixx="2.79091492195278E-05" ixy="-5.25179362037111E-08" ixz="-3.35339173907037E-07" iyy="4.4352692396792E-05" iyz="2.48697749463284E-08" izz="6.94753437602219E-05" />
    </inertial>
    <visual>
      <origin xyz="0 0 0" rpy="0 0 0" />
      <geometry>
        <mesh filename="package://robot/meshes/Lidar_link.STL" />
      </geometry>
      <material name="">
        <color rgba="0.792156862745098 0.819607843137255 0.933333333333333 1" />
      </material>
    </visual>
    <collision>
      <origin xyz="0 0 0" rpy="0 0 0" />
      <geometry>
        <mesh filename="package://robot/meshes/Lidar_link.STL" />
      </geometry>
    </collision>
  </link>
  <joint name="Lidar_joint" type="fixed">
    <origin xyz="-0.016395 -0.00015817 0.1378" rpy="0 0 0" />
    <parent link="base_link" />
    <child link="Lidar_link" />
    <axis xyz="0 0 0" />
  </joint>


  <!-- BANHPHAI_LINK -->
  <link name="Banhphai_link">
    <inertial>
      <origin xyz="-4.53667395212964E-08 -0.00502202789200742 3.22490651752383E-08" rpy="0 0 0" />
      <mass value="0.2" />
      <inertia ixx="6.56569251280724E-06" ixy="-1.31434017817046E-11" ixz="9.73665005891721E-13" iyy="1.2886210200016E-05" iyz="9.34302140636397E-12" izz="6.56569319038927E-06" />
    </inertial>
    <visual>
      <origin xyz="0 0 0" rpy="0 0 0" />
      <geometry>
        <mesh filename="package://robot/meshes/Banhphai_link.STL" />
      </geometry>
      <material name="">
        <color rgba="0.792156862745098 0.819607843137255 0.933333333333333 1" />
      </material>
    </visual>
    <collision>
      <origin xyz="0 0 0" rpy="0 0 0" />
      <geometry>
        <mesh filename="package://robot/meshes/Banhphai_link.STL" />
      </geometry>
    </collision>
  </link>
  <joint name="Banhphai_joint" type="continuous">
    <origin xyz="-0.00032385 -0.128 0.032493" rpy="0 0 0" />
    <parent link="base_link" />
    <child link="Banhphai_link" />
    <axis xyz="0 1 0" />
    <dynamics damping="1.0" friction="1"/>
    <limit effort="1000" velocity="100.0"/>
  </joint>

  <!-- BANHTRAI_LINK -->
  <link name="Banhtrai_link">
    <inertial>
      <origin xyz="-5.36683171219882E-08 0.00502202789200748 -1.47599118396208E-08" rpy="0 0 0" />
      <mass value="0.2" />
      <inertia ixx="6.56569196565971E-06" ixy="1.55484890731128E-11" ixz="-5.27177181681451E-13" iyy="1.2886210200016E-05" iyz="4.27616029738222E-12" izz="6.56569373753681E-06" />
    </inertial>
    <visual>
      <origin xyz="0 0 0" rpy="0 0 0" />
      <geometry>
        <mesh filename="package://robot/meshes/Banhtrai_link.STL" />
      </geometry>
      <material name="">
        <color rgba="0.792156862745098 0.819607843137255 0.933333333333333 1" />
      </material>
    </visual>
    <collision>
      <origin xyz="0 0 0" rpy="0 0 0" />
      <geometry>
        <mesh filename="package://robot/meshes/Banhtrai_link.STL" />
      </geometry>
    </collision>
  </link>
  <joint name="Banhtrai_joint" type="continuous">
    <origin xyz="-0.00032385 0.128 0.032493" rpy="0 0 0" />
    <parent link="base_link" />
    <child link="Banhtrai_link" />
    <axis xyz="0 1 0" />
    <dynamics damping="1.0" friction="1.0"/>
    <limit effort="1000" velocity="100.0"/>
  </joint>
  <!-- plugin -->
  <gazebo>
    <plugin name="diff_drive_controller" filename="libgazebo_ros_diff_drive.so">
      <rosDebugLevel>Info</rosDebugLevel>
      <commandTopic>cmd_vel</commandTopic>
      <odometryTopic>odom_combined</odometryTopic>
      <odometryFrame>odom_combined</odometryFrame>
      <robotBaseFrame>base_footprint</robotBaseFrame>
      <publishWheelTF>false</publishWheelTF>
      <publishOdomTF>true</publishOdomTF>
      <publishWheelJointState>true</publishWheelJointState>
      <wheelSeparation>0.256</wheelSeparation>
      <wheelDiameter>0.0655</wheelDiameter>
      <wheelAcceleration>10.0</wheelAcceleration>
      <wheelTorque>100.0</wheelTorque>
      <updateRate>50.0</updateRate>
      <leftJoint>Banhtrai_joint</leftJoint>
      <rightJoint>Banhphai_joint</rightJoint>
      <odometrySource>encoder</odometrySource>
      <publishTf>1</publishTf>
    </plugin>
  </gazebo>


  <!-- pluginlidar -->


  <gazebo reference="Lidar_link">
    <sensor type="ray" name="lidar_sensor">
      <pose>0 0 0 0 0 0</pose>
      <visualize>true</visualize>
      <update_rate>30</update_rate>
      <ray>
        <scan>
          <horizontal>
            <samples>720</samples>
            <resolution>1</resolution>
            <min_angle>-1.5708</min_angle>
            <max_angle>1.5708</max_angle>
          </horizontal>
        </scan>
        <range>
          <min>0.1</min>
          <max>10.0</max>
          <resolution>0.01</resolution>
        </range>
        <noise>
          <type>gaussian</type>
          <mean>0.0</mean>
          <stddev>0.01</stddev>
        </noise>
      </ray>
      <plugin name="gazebo_ros_laser" filename="libgazebo_ros_laser.so">
        <topicName>/base_scan</topicName>
        <frameName>Lidar_link</frameName>
      </plugin>
    </sensor>
  </gazebo>

<!-- //them he so ma sat -->
<gazebo reference="Banhphai_link">
  <mu1>1</mu1>
  <mu2>2</mu2>
  <kp>1000000.0</kp>
  <kd>1</kd>
  <material>Gazebo/Black</material>
</gazebo>

<gazebo reference="Banhtrai_link">
  <mu1>1</mu1>
  <mu2>2</mu2>
  <kp>1000000.0</kp>
  <kd>1</kd>
  <material>Gazebo/Black</material>
</gazebo>

<gazebo reference="Banhdahuong_link">
  <mu1>1</mu1>
  <mu2>2</mu2>
  <kp>1000000.0</kp>
  <kd>1</kd>
  <material>Gazebo/Black</material>
</gazebo>
<!-- them mau cho cac phan  -->
<gazebo reference="Lidar_link">
  <material>Gazebo/Blue</material>
</gazebo>
<gazebo reference="Base_link">
  <material>Gazebo/White</material>
</gazebo>
</robot>
